<?xml version="1.0"?> 
<robot  xmlns:xacro="http://ros.org/wiki/xacro" name="smartcar">

  <!-- Length between front and real wheel axel -->
  <xacro:property name="wheelbase" value="0.283" />    

  <!-- Width of the car chassis, excluding wheel width in each side -->
  <xacro:property name="chassis_width" value="0.206" /> 

  <!-- Height of the car chassis -->
  <xacro:property name="chassis_height" value="0.05" /> 
  <xacro:property name="ground_offset" value="0.03" />
  <xacro:property name="wheel_radius" value="0.0415" />
  <xacro:property name="wheel_length" value="0.042" />
  <xacro:property name="laser_distance_from_base_link" value="0.05" />
  <xacro:property name="laser_height" value="0.04" />
  <xacro:property name="laser_radius" value="0.035" />
  <xacro:property name="wheel_axle_length" value="0.035" />
  <xacro:property name="wheel_axle_radius" value="0.005" />

  <!-- Length of the car chassis / -->
  <xacro:property name="chessis_length" value="0.34" /> 

  <xacro:include filename="$(find mushr_description)/robots/smartcar_marcos.xacro" />

  <xacro:include filename="$(find mushr_description)/robots/smartcar.gazebo" />

  <link name="base_link" />

  <link name="chassis">
    <visual>
            <geometry>
                <box size="${chessis_length} ${chassis_width - wheel_axle_length * 2} ${chassis_height}"/>
            </geometry>

            <origin rpy="0 0 ${pi/2}" xyz="0 0 0"/>

            <material name="blue">
                <color rgba="0 .5 .8 1"/>
            </material>
        </visual>
  </link>

  <joint name="base_link_joint" type="fixed">
    <origin xyz="0 0 ${ground_offset}" rpy="0 0 0" />
    <parent link="base_link" />
    <child link="chassis" />
  </joint>

  <link name="chassis_inertia">
    	<inertial>
	  <mass value="10.0" />
	  <inertia ixx="0.010609" ixy="0"          ixz="0"
		                  iyy="0.050409"   iyz="0"
		                                   izz="0.05865" />
    	</inertial>
  </link>

  <joint name="chassis_inertia_joint" type="fixed">
    <origin xyz="0 0 0" rpy="0 0 0" />
    <parent link="chassis" />
    <child link="chassis_inertia" />
  </joint>

	<xacro:four_wheel_axles/>
	<xacro:smartcar_wheel prefix="rear_right"/>
	<xacro:smartcar_wheel prefix="rear_left"/>
	<xacro:smartcar_wheel prefix="front_left"/>
	<xacro:smartcar_wheel prefix="front_right"/>

    <joint name="rear_right_wheel_throttle" type="continuous">  
        <axis xyz="0 0 -1"/>  
        <parent link="chassis"/>  
        <child link="rear_right_wheel"/>  
        <origin rpy="0 ${pi/2} 0" xyz=" ${chassis_width / 2 + wheel_length / 2} ${-wheelbase / 2} 0"/>  
        <limit effort="10" velocity="1000"/>  
        <joint_properties damping="0.0" friction="0.0"/>  
    </joint>
  <xacro:wheel_transmission name="rear_right_wheel"/>
    
    <joint name="rear_left_wheel_throttle" type="continuous">  
        <axis xyz="0 0 -1"/>  
        <parent link="chassis"/>  
        <child link="rear_left_wheel"/>  
        <origin rpy="0 ${pi/2} 0" xyz=" ${-chassis_width / 2 - wheel_length / 2} ${-wheelbase / 2} 0"/>  
        <limit effort="10" velocity="1000"/> 
        <joint_properties damping="0.0" friction="0.0"/>  
    </joint>
  <xacro:wheel_transmission name="rear_left_wheel"/>

  <link name="right_steering_hinge">
    <inertial>
      <xacro:steering_hinge_inertial_params />
    </inertial>
    <visual>
      <xacro:right_steering_hinge_geometry />
      <material name="grey" />
    </visual>
  </link>

  <joint name="right_steering_hinge_joint" type="revolute">
    <origin rpy="0 ${pi/2} 0" xyz=" ${chassis_width / 2} ${wheelbase / 2} 0"/>  
    <parent link="chassis" />
    <child link="right_steering_hinge" />
    <axis xyz="-1 0 0" />
    <limit lower="-1.0" upper="1.0" effort="10" velocity="1000" />
  </joint>
   <xacro:steering_hinge_transmission name="right_steering"/>

  <joint name="front_right_wheel_throttle" type="continuous">
    <origin xyz="0 0 ${wheel_length / 2}" rpy="0 0 0" />
    <parent link="right_steering_hinge" />
    <child link="front_right_wheel" />
    <axis xyz="0 0 -1" />
    <limit effort="10" velocity="1000"/>
  </joint>
  <xacro:wheel_transmission name="front_right_wheel"/>
  
  <link name="left_steering_hinge">
    <inertial>
      <xacro:steering_hinge_inertial_params />
    </inertial>
    <visual>
      <xacro:left_steering_hinge_geometry />
      <material name="grey" />
    </visual>
  </link>

  <joint name="left_steering_hinge_joint" type="revolute">
    <origin rpy="0 ${pi/2} 0" xyz=" ${-chassis_width / 2} ${wheelbase / 2} 0"/>
    <parent link="chassis" />
    <child link="left_steering_hinge" />
    <axis xyz="-1 0 0" />
    <limit lower="-1.0" upper="1.0" effort="10" velocity="1000" />
  </joint>
  <xacro:steering_hinge_transmission name="left_steering"/>

  <joint name="front_left_wheel_throttle" type="continuous">
    <origin xyz="0 0 ${-wheel_length / 2}" rpy="0 0 0" />
    <parent link="left_steering_hinge" />
    <child link="front_left_wheel" />
    <axis xyz="0 0 -1" />
    <limit effort="10" velocity="1000" />
  </joint>
  <xacro:wheel_transmission name="front_left_wheel"/> 

    
    <link name="camera_link">  
        <visual>  
            <geometry>  
                <box size=".02 .03 .03"/>  
            </geometry>  
            <material name="white">
                <color rgba="1 1 1 1"/>  
            </material>  
        </visual>
    	<collision>
      	  <geometry>
        	<box size="0.02 .03 .03"/>
     	  </geometry>
    	</collision>
    	<inertial>
      	  <mass value="0.1"/>
      	  <inertia ixx="0.000010833" iyy="0.000010833" izz="0.000015" ixy="0" ixz="0" iyz="0"/>
    	</inertial>
    </link>  
    
    <joint name="tobox" type="fixed">  
        <parent link="base_link"/>  
        <child link="camera_link"/>  
        <origin xyz="0 0.08 0.025" rpy="0 0 1.57"/>  
    </joint>
    <gazebo reference="camera">
        <material>Gazebo/Blue</material>
    </gazebo> 


</robot>

